Workbook

Sheet Datos Hornos Reflujo
A1: Dispositivo | B1: Timestamp | C1: Temperatura (°C)
A2: Horno Principal | B2: 2025-08-01 13:42:09 | C2: 39.04
A3: Horno Secundario | B3: 2025-08-01 13:42:10 | C3: 30.98
A4: Horno Principal | B4: 2025-08-01 13:42:10 | C4: 39.08
A5: Horno Secundario | B5: 2025-08-01 13:42:11 | C5: 30.98
A6: Horno Principal | B6: 2025-08-01 13:42:11 | C6: 39.08
A7: Horno Secundario | B7: 2025-08-01 13:42:12 | C7: 31
A8: Horno Principal | B8: 2025-08-01 13:42:12 | C8: 39.06
A9: Horno Secundario | B9: 2025-08-01 13:42:13 | C9: 30.98
A10: Horno Principal | B10: 2025-08-01 13:42:13 | C10: 39.12
A11: Horno Secundario | B11: 2025-08-01 13:42:14 | C11: 30.95
A12: Horno Principal | B12: 2025-08-01 13:42:14 | C12: 39.17
A13: Horno Secundario | B13: 2025-08-01 13:42:15 | C13: 30.9
... A3852: Horno Secundario | B3852: 2025-08-01 14:16:29 | C3852: 33.17

Sheet uno
A1: Timestamp | B1: Temperatura (°C)
A2: =IF('Datos Hornos Reflujo'!A2="Horno Principal",'Datos Hornos Reflujo'!B2,0) -> 2025-08-01 13:42:09 | B2: =IF('Datos Hornos Reflujo'!A2="Horno Principal",'Datos Hornos Reflujo'!C2,0) -> 39.04
A3: =IF('Datos Hornos Reflujo'!A3="Horno Principal",'Datos Hornos Reflujo'!B3,) -> 0 | B3: =IF('Datos Hornos Reflujo'!A3="Horno Principal",'Datos Hornos Reflujo'!C3,0) -> 0
A4: =IF('Datos Hornos Reflujo'!A4="Horno Principal",'Datos Hornos Reflujo'!B4,0) -> 2025-08-01 13:42:10 | B4: =IF('Datos Hornos Reflujo'!A4="Horno Principal",'Datos Hornos Reflujo'!C4,0) -> 39.08
A5: =IF('Datos Hornos Reflujo'!A5="Horno Principal",'Datos Hornos Reflujo'!B5,0) -> 0 | B5: =IF('Datos Hornos Reflujo'!A5="Horno Principal",'Datos Hornos Reflujo'!C5,0) -> 0
A6: =IF('Datos Hornos Reflujo'!A6="Horno Principal",'Datos Hornos Reflujo'!B6,0) -> 2025-08-01 13:42:11 | B6: =IF('Datos Hornos Reflujo'!A6="Horno Principal",'Datos Hornos Reflujo'!C6,0) -> 39.08
A7: =IF('Datos Hornos Reflujo'!A7="Horno Principal",'Datos Hornos Reflujo'!B7,0) -> 0 | B7: =IF('Datos Hornos Reflujo'!A7="Horno Principal",'Datos Hornos Reflujo'!C7,0) -> 0
A8: =IF('Datos Hornos Reflujo'!A8="Horno Principal",'Datos Hornos Reflujo'!B8,0) -> 2025-08-01 13:42:12 | B8: =IF('Datos Hornos Reflujo'!A8="Horno Principal",'Datos Hornos Reflujo'!C8,0) -> 39.06
A9: =IF('Datos Hornos Reflujo'!A9="Horno Principal",'Datos Hornos Reflujo'!B9,0) -> 0 | B9: =IF('Datos Hornos Reflujo'!A9="Horno Principal",'Datos Hornos Reflujo'!C9,0) -> 0
A10: =IF('Datos Hornos Reflujo'!A10="Horno Principal",'Datos Hornos Reflujo'!B10,0) -> 2025-08-01 13:42:13 | B10: =IF('Datos Hornos Reflujo'!A10="Horno Principal",'Datos Hornos Reflujo'!C10,0) -> 39.12
A11: =IF('Datos Hornos Reflujo'!A11="Horno Principal",'Datos Hornos Reflujo'!B11,0) -> 0 | B11: =IF('Datos Hornos Reflujo'!A11="Horno Principal",'Datos Hornos Reflujo'!C11,0) -> 0
A12: =IF('Datos Hornos Reflujo'!A12="Horno Principal",'Datos Hornos Reflujo'!B12,0) -> 2025-08-01 13:42:14 | B12: =IF('Datos Hornos Reflujo'!A12="Horno Principal",'Datos Hornos Reflujo'!C12,0) -> 39.17
A13: =IF('Datos Hornos Reflujo'!A13="Horno Principal",'Datos Hornos Reflujo'!B13,0) -> 0 | B13: =IF('Datos Hornos Reflujo'!A13="Horno Principal",'Datos Hornos Reflujo'!C13,0) -> 0
A14: =IF('Datos Hornos Reflujo'!A14="Horno Principal",'Datos Hornos Reflujo'!B14,0) -> 2025-08-01 13:42:15 | B14: =IF('Datos Hornos Reflujo'!A14="Horno Principal",'Datos Hornos Reflujo'!C14,0) -> 39.16
A15: =IF('Datos Hornos Reflujo'!A15="Horno Principal",'Datos Hornos Reflujo'!B15,0) -> 0 | B15: =IF('Datos Hornos Reflujo'!A15="Horno Principal",'Datos Hornos Reflujo'!C15,0) -> 0
... A3852: =IF('Datos Hornos Reflujo'!A3852="Horno Principal",'Datos Hornos Reflujo'!B3852,0) -> 0 | B3852: =IF('Datos Hornos Reflujo'!A3852="Horno Principal",'Datos Hornos Reflujo'!C3852,0) -> 0

Sheet dos
A1: Timestamp | B1: Temperatura (°C) | C1: velocidad | D1: aceleración
A2: =IF('Datos Hornos Reflujo'!A3="Horno Secundario",'Datos Hornos Reflujo'!B3,) -> 2025-08-01 13:42:10 | B2: =IF('Datos Hornos Reflujo'!A3="Horno Secundario",'Datos Hornos Reflujo'!C3,0) -> 30.98 | C2: 0 | D2: 0
A3: =IF('Datos Hornos Reflujo'!A5="Horno Secundario",'Datos Hornos Reflujo'!B5,) -> 2025-08-01 13:42:11 | B3: =IF('Datos Hornos Reflujo'!A5="Horno Secundario",'Datos Hornos Reflujo'!C5,0) -> 30.98 | C3: =(B3-B2) -> 0 | D3: =(C3-C2) -> 0
A4: =IF('Datos Hornos Reflujo'!A7="Horno Secundario",'Datos Hornos Reflujo'!B7,) -> 2025-08-01 13:42:12 | B4: =IF('Datos Hornos Reflujo'!A7="Horno Secundario",'Datos Hornos Reflujo'!C7,0) -> 31 | C4: =(B4-B3) -> 0.02 | D4: =(C4-C3) -> 0.02
A5: =IF('Datos Hornos Reflujo'!A9="Horno Secundario",'Datos Hornos Reflujo'!B9,) -> 2025-08-01 13:42:13 | B5: =IF('Datos Hornos Reflujo'!A9="Horno Secundario",'Datos Hornos Reflujo'!C9,0) -> 30.98 | C5: =(B5-B4) -> -0.02 | D5: =(C5-C4) -> -0.04
A6: =IF('Datos Hornos Reflujo'!A11="Horno Secundario",'Datos Hornos Reflujo'!B11,) -> 2025-08-01 13:42:14 | B6: =IF('Datos Hornos Reflujo'!A11="Horno Secundario",'Datos Hornos Reflujo'!C11,0) -> 30.95 | C6: =(B6-B5) -> -0.03 | D6: =(C6-C5) -> -0.01
A7: =IF('Datos Hornos Reflujo'!A13="Horno Secundario",'Datos Hornos Reflujo'!B13,) -> 2025-08-01 13:42:15 | B7: =IF('Datos Hornos Reflujo'!A13="Horno Secundario",'Datos Hornos Reflujo'!C13,0) -> 30.9 | C7: =(B7-B6) -> -0.05 | D7: =(C7-C6) -> -0.02
A8: =IF('Datos Hornos Reflujo'!A15="Horno Secundario",'Datos Hornos Reflujo'!B15,) -> 2025-08-01 13:42:16 | B8: =IF('Datos Hornos Reflujo'!A15="Horno Secundario",'Datos Hornos Reflujo'!C15,0) -> 30.9 | C8: =(B8-B7) -> 0 | D8: =(C8-C7) -> 0.05
A9: =IF('Datos Hornos Reflujo'!A16="Horno Secundario",'Datos Hornos Reflujo'!B16,) -> 2025-08-01 13:42:17 | B9: =IF('Datos Hornos Reflujo'!A16="Horno Secundario",'Datos Hornos Reflujo'!C16,0) -> 30.88 | C9: =(B9-B8) -> -0.02 | D9: =(C9-#REF!) -> #REF!
A10: =IF('Datos Hornos Reflujo'!A18="Horno Secundario",'Datos Hornos Reflujo'!B18,) -> 2025-08-01 13:42:18 | B10: =IF('Datos Hornos Reflujo'!A18="Horno Secundario",'Datos Hornos Reflujo'!C18,0) -> 30.9 | C10: =(B10-B9) -> 0.02 | D10: =(C10-C9) -> 0.04
A11: =IF('Datos Hornos Reflujo'!A22="Horno Secundario",'Datos Hornos Reflujo'!B22,) -> 2025-08-01 13:42:20 | B11: =IF('Datos Hornos Reflujo'!A22="Horno Secundario",'Datos Hornos Reflujo'!C22,0) -> 30.8 | C11: =(B11-B10) -> -0.1 | D11: =(C11-#REF!) -> #REF!
A12: =IF('Datos Hornos Reflujo'!A24="Horno Secundario",'Datos Hornos Reflujo'!B24,) -> 2025-08-01 13:42:21 | B12: =IF('Datos Hornos Reflujo'!A24="Horno Secundario",'Datos Hornos Reflujo'!C24,0) -> 30.83 | C12: =(B12-B11) -> 0.03 | D12: =(C12-C11) -> 0.13
A13: =IF('Datos Hornos Reflujo'!A26="Horno Secundario",'Datos Hornos Reflujo'!B26,) -> 2025-08-01 13:42:22 | B13: =IF('Datos Hornos Reflujo'!A26="Horno Secundario",'Datos Hornos Reflujo'!C26,0) -> 30.8 | C13: =(B13-B12) -> -0.03 | D13: =(C13-C12) -> -0.06
A14: =IF('Datos Hornos Reflujo'!A28="Horno Secundario",'Datos Hornos Reflujo'!B28,) -> 2025-08-01 13:42:23 | B14: =IF('Datos Hornos Reflujo'!A28="Horno Secundario",'Datos Hornos Reflujo'!C28,0) -> 30.83 | C14: =(B14-B13) -> 0.03 | D14: =(C14-C13) -> 0.06
A15: =IF('Datos Hornos Reflujo'!A3="Horno Secundario",'Datos Hornos Reflujo'!B3,) -> 2025-08-01 13:42:10 | B15: =IF('Datos Hornos Reflujo'!A30="Horno Secundario",'Datos Hornos Reflujo'!C30,0) -> 0
A16: =IF('Datos Hornos Reflujo'!A31="Horno Secundario",'Datos Hornos Reflujo'!B31,) -> 2025-08-01 13:42:25 | B16: =IF('Datos Hornos Reflujo'!A31="Horno Secundario",'Datos Hornos Reflujo'!C31,0) -> 30.9 | C16: =B16-#REF! -> #REF! | D16: =(C16-#REF!) -> #REF!
A17: =IF('Datos Hornos Reflujo'!A34="Horno Secundario",'Datos Hornos Reflujo'!B34,) -> 2025-08-01 13:42:27 | B17: =IF('Datos Hornos Reflujo'!A34="Horno Secundario",'Datos Hornos Reflujo'!C34,0) -> 30.9 | C17: =B17-#REF! -> #REF! | D17: =(C17-#REF!) -> #REF!
A18: =IF('Datos Hornos Reflujo'!A35="Horno Secundario",'Datos Hornos Reflujo'!B35,) -> 2025-08-01 13:42:28 | B18: =IF('Datos Hornos Reflujo'!A35="Horno Secundario",'Datos Hornos Reflujo'!C35,0) -> 30.92 | C18: =B18-#REF! -> #REF! | D18: =(C18-#REF!) -> #REF!
A19: =IF('Datos Hornos Reflujo'!A37="Horno Secundario",'Datos Hornos Reflujo'!B37,) -> 2025-08-01 13:42:29 | B19: =IF('Datos Hornos Reflujo'!A37="Horno Secundario",'Datos Hornos Reflujo'!C37,0) -> 30.9 | C19: =B19-B18 -> -0.02 | D19: =(C19-C18) -> #REF!
A20: =IF('Datos Hornos Reflujo'!A39="Horno Secundario",'Datos Hornos Reflujo'!B39,) -> 2025-08-01 13:42:30 | B20: =IF('Datos Hornos Reflujo'!A39="Horno Secundario",'Datos Hornos Reflujo'!C39,0) -> 30.98 | C20: =B20-B19 -> 0.08 | D20: =(C20-C19) -> 0.1
A21: =IF('Datos Hornos Reflujo'!A41="Horno Secundario",'Datos Hornos Reflujo'!B41,) -> 2025-08-01 13:42:31 | B21: =IF('Datos Hornos Reflujo'!A41="Horno Secundario",'Datos Hornos Reflujo'!C41,0) -> 30.98 | C21: =B21-B20 -> 0 | D21: =(C21-C20) -> -0.08
A22: =IF('Datos Hornos Reflujo'!A43="Horno Secundario",'Datos Hornos Reflujo'!B43,) -> 2025-08-01 13:42:32 | B22: =IF('Datos Hornos Reflujo'!A43="Horno Secundario",'Datos Hornos Reflujo'!C43,0) -> 30.95 | C22: =B22-B21 -> -0.03 | D22: =(C22-C21) -> -0.03
A23: =IF('Datos Hornos Reflujo'!A45="Horno Secundario",'Datos Hornos Reflujo'!B45,) -> 2025-08-01 13:42:33 | B23: =IF('Datos Hornos Reflujo'!A45="Horno Secundario",'Datos Hornos Reflujo'!C45,0) -> 30.98 | C23: =B23-B22 -> 0.03 | D23: =(C23-C22) -> 0.06
A24: =IF('Datos Hornos Reflujo'!A47="Horno Secundario",'Datos Hornos Reflujo'!B47,) -> 2025-08-01 13:42:34 | B24: =IF('Datos Hornos Reflujo'!A47="Horno Secundario",'Datos Hornos Reflujo'!C47,0) -> 30.95 | C24: =B24-B23 -> -0.03 | D24: =(C24-C23) -> -0.06
A25: =IF('Datos Hornos Reflujo'!A49="Horno Secundario",'Datos Hornos Reflujo'!B49,) -> 2025-08-01 13:42:35 | B25: =IF('Datos Hornos Reflujo'!A49="Horno Secundario",'Datos Hornos Reflujo'!C49,0) -> 30.98 | C25: =B25-B24 -> 0.03 | D25: =(C25-C24) -> 0.06
A26: =IF('Datos Hornos Reflujo'!A5="Horno Secundario",'Datos Hornos Reflujo'!B5,) -> 2025-08-01 13:42:11 | B26: =IF('Datos Hornos Reflujo'!A50="Horno Secundario",'Datos Hornos Reflujo'!C50,0) -> 0
A27: =IF('Datos Hornos Reflujo'!A51="Horno Secundario",'Datos Hornos Reflujo'!B51,) -> 2025-08-01 13:42:36 | B27: =IF('Datos Hornos Reflujo'!A51="Horno Secundario",'Datos Hornos Reflujo'!C51,0) -> 30.98 | C27: =(B27-B25) -> 0 | D27: =(C27-C25) -> -0.03
A28: =IF('Datos Hornos Reflujo'!A53="Horno Secundario",'Datos Hornos Reflujo'!B53,) -> 2025-08-01 13:42:37 | B28: =IF('Datos Hornos Reflujo'!A53="Horno Secundario",'Datos Hornos Reflujo'!C53,0) -> 31 | C28: =(B28-B27) -> 0.02 | D28: =(C28-C27) -> 0.02
A29: =IF('Datos Hornos Reflujo'!A54="Horno Secundario",'Datos Hornos Reflujo'!B54,) -> 2025-08-01 13:42:38 | B29: =IF('Datos Hornos Reflujo'!A54="Horno Secundario",'Datos Hornos Reflujo'!C54,0) -> 31 | C29: =(B29-#REF!) -> #REF! | D29: =(C29-#REF!) -> #REF!
A30: =IF('Datos Hornos Reflujo'!A56="Horno Secundario",'Datos Hornos Reflujo'!B56,) -> 2025-08-01 13:42:39 | B30: =IF('Datos Hornos Reflujo'!A56="Horno Secundario",'Datos Hornos Reflujo'!C56,0) -> 31.05 | C30: =(B30-B29) -> 0.05 | D30: =(C30-C29) -> #REF!
A31: =IF('Datos Hornos Reflujo'!A58="Horno Secundario",'Datos Hornos Reflujo'!B58,) -> 2025-08-01 13:42:40 | B31: =IF('Datos Hornos Reflujo'!A58="Horno Secundario",'Datos Hornos Reflujo'!C58,0) -> 31.08 | C31: =(B31-B30) -> 0.03 | D31: =(C31-C30) -> -0.02
A32: =IF('Datos Hornos Reflujo'!A62="Horno Secundario",'Datos Hornos Reflujo'!B62,) -> 2025-08-01 13:42:42 | B32: =IF('Datos Hornos Reflujo'!A62="Horno Secundario",'Datos Hornos Reflujo'!C62,0) -> 31.2 | C32: =(B32-#REF!) -> #REF! | D32: =(C32-#REF!) -> #REF!
A33: =IF('Datos Hornos Reflujo'!A64="Horno Secundario",'Datos Hornos Reflujo'!B64,) -> 2025-08-01 13:42:43 | B33: =IF('Datos Hornos Reflujo'!A64="Horno Secundario",'Datos Hornos Reflujo'!C64,0) -> 31.23 | C33: =(B33-B32) -> 0.03 | D33: =(C33-C32) -> #REF!
A34: =IF('Datos Hornos Reflujo'!A66="Horno Secundario",'Datos Hornos Reflujo'!B66,) -> 2025-08-01 13:42:44 | B34: =IF('Datos Hornos Reflujo'!A66="Horno Secundario",'Datos Hornos Reflujo'!C66,0) -> 31.27 | C34: =(B34-B33) -> 0.04 | D34: =(C34-C33) -> 0.01
A35: =IF('Datos Hornos Reflujo'!A68="Horno Secundario",'Datos Hornos Reflujo'!B68,) -> 2025-08-01 13:42:45 | B35: =IF('Datos Hornos Reflujo'!A68="Horno Secundario",'Datos Hornos Reflujo'!C68,0) -> 31.3 | C35: =(B35-B34) -> 0.03 | D35: =(C35-C34) -> -0.01
A36: =IF('Datos Hornos Reflujo'!A7="Horno Secundario",'Datos Hornos Reflujo'!B7,) -> 2025-08-01 13:42:12 | B36: =IF('Datos Hornos Reflujo'!A70="Horno Secundario",'Datos Hornos Reflujo'!C70,0) -> 31.35 | C36: =(B36-B35) -> 0.05 | D36: =(C36-C35) -> 0.02
A37: =IF('Datos Hornos Reflujo'!A72="Horno Secundario",'Datos Hornos Reflujo'!B72,) -> 2025-08-01 13:42:47 | B37: =IF('Datos Hornos Reflujo'!A72="Horno Secundario",'Datos Hornos Reflujo'!C72,0) -> 31.45 | C37: =(B37-B36) -> 0.1 | D37: =(C37-C36) -> 0.05
A38: =IF('Datos Hornos Reflujo'!A74="Horno Secundario",'Datos Hornos Reflujo'!B74,) -> 2025-08-01 13:42:48 | B38: =IF('Datos Hornos Reflujo'!A74="Horno Secundario",'Datos Hornos Reflujo'!C74,0) -> 31.52 | C38: =(B38-B37) -> 0.07 | D38: =(C38-C37) -> -0.03
A39: =IF('Datos Hornos Reflujo'!A75="Horno Secundario",'Datos Hornos Reflujo'!B75,) -> 2025-08-01 13:42:49 | B39: =IF('Datos Hornos Reflujo'!A75="Horno Secundario",'Datos Hornos Reflujo'!C75,0) -> 31.62 | C39: =(B39-#REF!) -> #REF! | D39: =(C39-#REF!) -> #REF!
A40: =IF('Datos Hornos Reflujo'!A77="Horno Secundario",'Datos Hornos Reflujo'!B77,) -> 2025-08-01 13:42:50 | B40: =IF('Datos Hornos Reflujo'!A77="Horno Secundario",'Datos Hornos Reflujo'!C77,0) -> 31.67 | C40: =(B40-B39) -> 0.05 | D40: =(C40-C39) -> #REF!
...
